<?xml version="1.0" ?>
<robot name="mad_bot">

    <link name="chassis">
        <inertial>
            <mass value="18"/>
            <inertia ixx="0.24" ixy="0" ixz="0" iyy="1.5" iyz="0" izz="1.74"/>
        </inertial>
        <visual>
            <geometry>
                <box size="1 0.4 0.4"/>
            </geometry>
            <material name="blue">
                <color rgba="0.5 0.5 1.0 1"/>
            </material>
        </visual>
        <collision>
            <geometry>
                <box size="1 0.4 0.4"/>
            </geometry>
        </collision>
    </link>

    <link name="left_wheel">
        <inertial>
            <mass value="2.5"/>
            <inertia ixx="0.12" ixy="0" ixz="0" iyy="0.12" iyz="0" izz="0.1"/>
        </inertial>
        <visual>
            <geometry>
                <cylinder radius="0.35" length="0.25"/>
            </geometry>
            <material name="gray">
                <color rgba="0.2 0.2 0.2 1"/>
            </material>
        </visual>
        <collision>
            <geometry>
                <cylinder radius="0.35" length="0.25"/>
            </geometry>
        </collision>
    </link>

    <link name="right_wheel">
        <inertial>
            <mass value="2.5"/>
            <inertia ixx="0.12" ixy="0" ixz="0" iyy="0.12" iyz="0" izz="0.1"/>
        </inertial>
        <visual>
            <geometry>
                <cylinder radius="0.35" length="0.25"/>
            </geometry>
            <material name="gray">
                <color rgba="0.2 0.2 0.2 1"/>
            </material>
        </visual>
        <collision>
            <geometry>
                <cylinder radius="0.35" length="0.25"/>
            </geometry>
        </collision>
    </link>

    <link name="caster_front">
        <inertial>
            <mass value="1"/>
            <inertia ixx="0.016" ixy="0" ixz="0" iyy="0.016" iyz="0" izz="0.016"/>
        </inertial>
        <visual>
            <geometry>
                <sphere radius="0.075"/>
            </geometry>
            <material name="green">
                <color rgba="0.0 1 0.0 1"/>
            </material>
        </visual>
        <collision>
            <geometry>
                <sphere radius="0.075"/>
            </geometry>
        </collision>
    </link>

    <link name="caster_back">
        <inertial>
            <mass value="1"/>
            <inertia ixx="0.016" ixy="0" ixz="0" iyy="0.016" iyz="0" izz="0.016"/>
        </inertial>
        <visual>
            <geometry>
                <sphere radius="0.075"/>
            </geometry>
            <material name="green">
                <color rgba="0.0 1 0.0 1"/>
            </material>
        </visual>
        <collision>
            <geometry>
                <sphere radius="0.075"/>
            </geometry>
        </collision>
    </link>

    <link name="camera_link">
        <inertial>
            <mass value="0.1"/>
            <inertia ixx="0.000166667" ixy="0" ixz="0" iyy="0.000166667" iyz="0" izz="0.000166667"/>
        </inertial>
        <visual>
            <geometry>
                <box size="0.1 0.1 0.05"/>
            </geometry>
        </visual>
        <collision>
            <geometry>
                <box size="0.1 0.1 0.05"/>
            </geometry>
        </collision>
    </link>

    <joint name="left_wheel_joint" type="revolute">
        <parent link="chassis"/>
        <child link="left_wheel"/>
        <origin xyz="0 0.325 0" rpy="0 0 0"/>
        <axis xyz="0 0 1"/>
        <limit lower="-1000" upper="1000" effort="10"/>
    </joint>

    <joint name="right_wheel_joint" type="revolute">
        <parent link="chassis"/>
        <child link="right_wheel"/>
        <origin xyz="0 -0.325 0" rpy="0 0 0"/>
        <axis xyz="0 0 1"/>
        <limit lower="-1000" upper="1000" effort="10"/>
    </joint>

    <joint name="front_caster_joint" type="ball">
        <parent link="chassis"/>
        <child link="caster_front"/>
        <origin xyz="-0.4 0 -0.275" rpy="0 0 0"/>
    </joint>

    <joint name="back_caster_joint" type="ball">
        <parent link="chassis"/>
        <child link="caster_back"/>
        <origin xyz="0.4 0 -0.275" rpy="0 0 0"/>
    </joint>

    <joint name="camera_joint" type="fixed">
        <parent link="chassis"/>
        <child link="camera_link"/>
        <origin xyz="0.3 0 0.225" rpy="0 0 0"/>
    </joint>

    <sensor name="camera" type="camera">
        <camera>
            <horizontal_fov>1.047</horizontal_fov>
            <image>
                <width>320</width>
                <height>240</height>
            </image>
            <clip>
                <near>0.1</near>
                <far>20</far>
            </clip>
        </camera>
        <always_on>1</always_on>
        <update_rate>60</update_rate>
        <visualize>true</visualize>
        <topic>camera</topic>
    </sensor>

</robot>
